<?xml version='1.0'?>

<robot name="rover" xmlns:xacro="http://www.ros.org/wiki/xacro">

  <xacro:include filename="$(find rover)/urdf/rover.gazebo"/>
  
<!-- Materials-->

  <material name="white">
      <color rgba = "1 1 1 1"/>
  </material>
   <material name="orange">
      <color rgba = "1 0.3 0.1 1"/>
  </material>
   <material name="blue">
      <color rgba = "0.2 0.2 1 1"/>
  </material>
  
  <material name="black">
      <color rgba = "0 0 0 1"/>
  </material>
  
  <material name="red">
      <color rgba = "1 0 0 1"/>
  </material>

<!-- Footprint -->

  <link name='footprint'>
    <origin xyz="0 0 0" rpy="0 0 0 "/>
  </link>

<!-- Chassis -->

  <joint name="chassis_joint" type="fixed">
    <parent link="footprint"/>
    <child link="chassis"/>
  </joint>

  <link name='chassis'>
    <pose>0 0 0.1 0 0 0</pose>

    <inertial>
      <mass value="20.0"/>
      <origin xyz="0 0 0" rpy=" 0 0 0"/>
      <inertia
          ixx="0.1" ixy="0" ixz="0"
          iyy="0.1" iyz="0"
          izz="0.1"
      />
    </inertial>

    <collision>
      <origin xyz="0 0 0" rpy=" 0 0 0"/>
      <geometry>
       <box size="0.8 0.5 0.05"/>
      </geometry>
    </collision>

    <visual>
      <origin xyz="0 0 0" rpy=" 0 0 0"/>
      <geometry>
       <box size="0.8 0.5 0.05"/>
      </geometry>
      <material name="blue"/>
    </visual>

  </link>

<!-- rear_left_wheel-->

  <joint name="rear_left_joint" type="continuous">
    <parent link="chassis"/>
    <child link="rear_left_wheel"/>
    <origin xyz="-0.25 0.29 0" rpy=" 0 0 0"/>
    <axis xyz="0 1 0"/>
    <dynamics damping="1.0" friction="1.0"/>
  </joint>

  <link name="rear_left_wheel">
    <visual>
    <origin rpy="1.5708 0 0" xyz="0 0 0" />
        <geometry>
            <cylinder radius="0.1" length="0.075"/>
        </geometry>
        <material name = "black"/>
    </visual>

    <collision>
    <origin rpy="1.5708 0 0" xyz="0 0 0" />
        <geometry>
            <cylinder radius="0.1" length="0.075"/>
        </geometry>
    </collision>

    <inertial>
      <mass value="2.0"/>
      <origin xyz="0 0 0" rpy=" 0 0 0"/>
      <inertia
        ixx="0.1" ixy="0" ixz="0"
        iyy="0.1" iyz="0"
        izz="0.1"
      />
    </inertial>
  </link>

<!-- rear_right_wheel-->

  <joint name="rear_right_joint" type="continuous">
    <parent link="chassis"/>
    <child link="rear_right_wheel"/>
    <origin xyz="-0.25 -0.29 0" rpy="0 0 0"/>
    <axis xyz="0 1 0"/>
    <dynamics damping="1.0" friction="1.0"/>
  </joint>

  <link name="rear_right_wheel">
    <visual>
    <origin rpy="1.5708 0 0" xyz="0 0 0" />
        <geometry>
            <cylinder radius="0.1" length="0.075"/>
        </geometry>
        <material name = "black"/>
    </visual>

    <collision>
      <origin rpy="1.5708 0 0" xyz="0 0 0" />
        <geometry>
            <cylinder radius="0.1" length="0.075"/>
        </geometry>
      </collision>

    <inertial>
      <mass value="2.0"/>
      <origin xyz="0 0 0" rpy=" 0 0 0"/>
      <inertia
        ixx="0.1" ixy="0" ixz="0"
        iyy="0.1" iyz="0"
        izz="0.1"
      />
    </inertial>

  </link>

<!-- front_left_wheel-->
  <joint name="front_left_joint" type="continuous">
    <parent link="chassis"/>
    <child link="front_left_wheel"/>
    <origin xyz="0.25 0.29 0" rpy="0 0 0"/>
    <axis xyz="0 1 0"/>
    <dynamics damping="1.0" friction="1.0"/>
  </joint>

  <link name="front_left_wheel">
    <visual>
    <origin rpy="1.5708 0 0" xyz="0 0 0" />
        <geometry>
            <cylinder radius="0.1" length="0.075"/>
        </geometry>
        <material name = "black"/>
    </visual>
        
    <collision>
    <origin rpy="1.5708 0 0" xyz="0 0 0" />
        <geometry>
            <cylinder radius="0.1" length="0.075"/>
        </geometry>
    </collision>

    <inertial>
      <mass value="2.0"/>
      <origin xyz="0 0 0" rpy=" 0 0 0"/>
      <inertia
        ixx="0.1" ixy="0" ixz="0"
        iyy="0.1" iyz="0"
        izz="0.1"
        />
    </inertial>

  </link>

<!-- front_right_wheel-->

  <joint name="front_right_joint" type="continuous">
        <parent link="chassis"/>
        <child link="front_right_wheel"/>
        <origin xyz="0.25 -0.29 0" rpy="0 0 0"/>
        <axis xyz="0 1 0"/>
        <dynamics damping="1.0" friction="1.0"/>
  </joint>

  <link name="front_right_wheel">
    <visual>
      <origin rpy="1.5708 0 0" xyz="0 0 0" />
        <geometry>
            <cylinder radius="0.1" length="0.075"/>
        </geometry>
        <material name = "black"/>
    </visual>

      <collision>
      <origin rpy="1.5708 0 0" xyz="0 0 0" />
        <geometry>
            <cylinder radius="0.1" length="0.075"/>
        </geometry>
      </collision>

    <inertial>
      <mass value="2.0"/>
      <origin xyz="0 0 0" rpy=" 0 0 0"/>
      <inertia
            ixx="0.1" ixy="0" ixz="0"
            iyy="0.1" iyz="0"
            izz="0.1"
      />
    </inertial>
  </link>

<!--staff-->

  <joint name="staff_link" type="fixed">
    <parent link="chassis"/>
    <child link="staff"/>
    <origin xyz="0.15 0 0.25" rpy="0 0 0"/>
  </joint>

  <link name="staff">
    <visual>
      <geometry>
          <cylinder radius="0.04" length="0.46"/>
      </geometry>
      <material name = "white"/>
    </visual>

    <collision>
      <geometry>
        <cylinder radius="0.04" length="0.46"/>
      </geometry>
    </collision>

    <inertial>
      <mass value="2.0"/>
      <origin xyz="0 0 0" rpy=" 0 0 0"/>
      <inertia
          ixx="0.1" ixy="0" ixz="0"
          iyy="0.1" iyz="0"
          izz="0.1"
      />
    </inertial>
  </link>

<!--face-->
  <joint name="face_link" type="fixed">
    <parent link="staff"/>
    <child link="face"/>
    <origin xyz="0.06 0 0.18" rpy="0 0 0"/>
  </joint>

  <link name="face">
    <visual>
      <geometry>
          <box size="0.04 0.3 0.1"/>
      </geometry>
      <material name = "orange"/>
    </visual>

    <collision>
      <geometry>
        <box size="0.04 0.3 0.1"/>
      </geometry>
    </collision>

    <inertial>
      <mass value="2.0"/>
      <origin xyz="0 0 0" rpy=" 0 0 0"/>
      <inertia
          ixx="0.1" ixy="0" ixz="0"
          iyy="0.1" iyz="0"
          izz="0.1"
      />
    </inertial>
  </link>

  <!--sensors-->
  <!--camera-->
  <joint name="camera_joint" type="fixed">
    <parent link="face"/>
    <child link="camera"/>
    <origin xyz="0.035 0.1 0"/>
  </joint>

  <link name="camera">
    <inertial>
      <mass value="0.1"/>
      <origin xyz="0 0 0" rpy=" 0 0 0"/>
      <inertia
        ixx="0.1" ixy="0" ixz="0"
        iyy="0.1" iyz="0"
        izz="0.1"
      />
    </inertial>

    <collision>
      <geometry>
        <box size="0.035 0.035 0.035"/>
      </geometry>  
    </collision>

    <visual>
      <geometry>
        <box size="0.035 0.035 0.035"/>
      </geometry>

      <material name="black"/>
    </visual>

  </link>

<!--imu-->

  <joint name="imu_joint" type="fixed">
    <parent link="chassis"/>
    <child link="imu"/>
    <origin xyz="0 0 0.05"/>
  </joint>

  <link name="imu">
    <inertial>
      <mass value="0.1"/>
      <origin xyz="0 0 0" rpy=" 0 0 0"/>
      <inertia
        ixx="0.1" ixy="0" ixz="0"
        iyy="0.1" iyz="0"
        izz="0.1"
      />
    </inertial>

    <collision>
    <origin xyz="0 0 0" rpy=" 0 0 0"/>
      <geometry>
        <box size="0.05 0.05 0.05"/>
      </geometry>  
    </collision>

    <visual>
      <geometry>
        <box size="0.05 0.05 0.05"/>
      </geometry>

      <material name="orange"/>
    </visual>

  </link>

<!-- LiDAR Sensor -->
  <joint name="lidar_joint" type="fixed">
    <parent link="face"/>
    <child link="lidar"/>
    <origin xyz="0.035 -0.1 0"/>
  </joint>

  <link name="lidar">
    <inertial>
      <mass value="0.1"/>
      <origin xyz="0 0 0" rpy=" 0 0 0"/>
      <inertia
        ixx="0.1" ixy="0" ixz="0"
        iyy="0.1" iyz="0"
        izz="0.1"
      />
    </inertial>

    <collision>
    <origin xyz="0 0 0" rpy=" 0 0 0"/>
      <geometry>
        <box size="0.035 0.035 0.035"/>
      </geometry>  
    </collision>

    <visual>
      <geometry>
        <box size="0.035 0.035 0.035"/>
      </geometry>

      <material name="blue"/>
    </visual>

  </link>

<!--zed2 camera-->

  <joint name="zed2_camera_joint" type="fixed">
    <parent link="face"/>
    <child link="zed2_camera"/>
    <origin xyz="0.035 0 0.00" rpy = "0 0 0 "/>
  </joint>

  <link name="zed2_camera">
    <inertial>
      <mass value="0.1"/>
      <origin xyz="0 0 0" rpy=" 0 0 0"/>
      <inertia
        ixx="0.1" ixy="0" ixz="0"
        iyy="0.1" iyz="0"
        izz="0.1"
      />
    </inertial>

    <collision>
    <origin xyz="0 0 0" rpy=" 0 0 0"/>
      <geometry>
        <box size="0.05 0.05 0.05"/>
      </geometry>  
    </collision>

    <visual>
      <geometry>
        <box size="0.05 0.05 0.05"/>
      </geometry>

      <material name="black"/>
    </visual>

  </link>

  <joint name="zed2_optical_joint" type="fixed">
    <origin xyz="0 0 0" rpy="${-pi/2} 0 ${-pi/2}"/>
    <parent link="zed2_camera"/>
    <child link="zed2_optical"/>
  </joint>

  <link name="zed2_optical">
  </link>

<!--gps-->

  <joint name="gps_joint" type="fixed">
    <parent link="chassis"/>
    <child link="gps"/>
    <origin xyz="0 0 -0.05"/>
  </joint>

  <link name="gps">
    <inertial>
      <mass value="0.1"/>
      <origin xyz="0 0 0" rpy=" 0 0 0"/>
      <inertia
        ixx="0.1" ixy="0" ixz="0"
        iyy="0.1" iyz="0"
        izz="0.1"
      />
    </inertial>

    <collision>
    <origin xyz="0 0 0" rpy=" 0 0 0"/>
      <geometry>
        <box size="0.05 0.05 0.05"/>
      </geometry>  
    </collision>

    <visual>
      <geometry>
        <box size="0.05 0.05 0.05"/>
      </geometry>

      <material name="red"/>
    </visual>

  </link>

</robot>
